Workbook

Sheet 02-02-26
A1: TABLEAU DE SUIVI JOURNALIER — CAMIONS (PRODUIT FINI & MATIÈRE PREMIÈRE)
B2: *
A3: Date | C3: 46055 | D3: Prix gasoil / L (par défaut) | F3: 2 | G3: Devise | I3: TND
A4: Saisir les valeurs en bleu. Les colonnes Montant global gasoil, Coût total et Résultat se calculent automatiquement.
A6: N° | B6: Matricule camion | C6: Nom chauffeur | D6: Type transport | E6: Destination | F6: Kilométrage du jour (km) | G6: Kilométrage global (km) | H6: Quantité gasoil (L) | I6: Prix gasoil / L | J6: Montant global gasoil | K6: Charges fixes | L6: Montant assurance | M6: Montant taxe | N6: Maintenance | O6: Charge personnel | P6: Coût total | Q6: Prix livraison | R6: Résultat (livraison - coût) | S6: Remarques
A7: 1 | B7: 8565 TU 257 | C7: CHOKAIRI | D7: PLATEAU | E7: TUNIS | F7: 800 | H7: 240 | I7: =$F$3 -> 2 | J7: =IF(OR(H7="",I7=""),0,H7*I7) -> 480 | K7: 400 | L7: 32 | M7: 20 | O7: 80 | P7: =J7+N(K7)+N(L7)+N(M7)+N(O7)+N7 -> 1012 | Q7: 500 | R7: =IF(Q7="","",N(Q7)-P7) -> -512
A8: 2 | B8: 8563 TU 257 | C8: LASSAD CHATAOUI | D8: PLATEAU | E8: TUNIS | F8: 800 | H8: 240 | I8: =$F$3 -> 2 | J8: =IF(OR(H8="",I8=""),0,H8*I8) -> 480 | K8: 400 | L8: 32 | M8: 20 | N8: 1070 | O8: 80 | P8: =J8+N(K8)+N(L8)+N(M8)+N(O8)+N8 -> 2082 | Q8: 500 | R8: =IF(Q8="","",N(Q8)-P8) -> -1582 | S8: VIDANGE
A9: 3 | B9: 5305 TU 236 | C9: HAMZA | D9: PLATEAU | E9: SOUSSE | F9: 300 | H9: 120 | I9: =$F$3 -> 2 | J9: =IF(OR(H9="",I9=""),0,H9*I9) -> 240 | K9: 80 | L9: 20 | M9: 20 | O9: 80 | P9: =J9+N(K9)+N(L9)+N(M9)+N(O9)+N9 -> 440 | Q9: 590 | R9: =IF(Q9="","",N(Q9)-P9) -> 150
A10: 4 | B10: 924 TU 98 | C10: IKRAMI | D10: PLATEAU | E10: DJERBA | F10: 340 | H10: 120 | I10: =$F$3 -> 2 | J10: =IF(OR(H10="",I10=""),0,H10*I10) -> 240 | K10: 80 | L10: 20 | M10: 20 | O10: 80 | P10: =J10+N(K10)+N(L10)+N(M10)+N(O10)+N10 -> 440 | Q10: 590 | R10: =IF(Q10="","",N(Q10)-P10) -> 150
A11: 5 | B11: 6980 TU 101 | C11: ABDELBARI | D11: PLATEAU | E11: KEBILI/GABES | F11: 434 | H11: 125 | I11: =$F$3 -> 2 | J11: =IF(OR(H11="",I11=""),0,H11*I11) -> 250 | K11: 80 | L11: 20 | M11: 20 | O11: 80 | P11: =J11+N(K11)+N(L11)+N(M11)+N(O11)+N11 -> 450 | Q11: 650 | R11: =IF(Q11="","",N(Q11)-P11) -> 200
A12: 6 | B12: 7775 TU 252 | C12: JAMIL | D12: PLATEAU | E12: MEHDIA/TUNIS | F12: 1220 | H12: 360 | I12: =$F$3 -> 2 | J12: =IF(OR(H12="",I12=""),0,H12*I12) -> 720 | K12: 400 | L12: 20 | M12: 20 | O12: 80 | P12: =J12+N(K12)+N(L12)+N(M12)+N(O12)+N12 -> 1240 | Q12: 1090 | R12: =IF(Q12="","",N(Q12)-P12) -> -150
A13: 7 | B13: 4176 TU 250 | C13: HEDI | D13: PLATEAU | E13: TUNIS | F13: 800 | H13: 240 | I13: =$F$3 -> 2 | J13: =IF(OR(H13="",I13=""),0,H13*I13) -> 480 | K13: 400 | L13: 32 | M13: 20 | O13: 80 | P13: =J13+N(K13)+N(L13)+N(M13)+N(O13)+N13 -> 1012 | Q13: 500 | R13: =IF(Q13="","",N(Q13)-P13) -> -512
A14: 8 | B14: 446 TU 228 | C14: MALEK | D14: PLATEAU | I14: =$F$3 -> 2 | J14: =IF(OR(H14="",I14=""),0,H14*I14) -> 0 | K14: 80 | L14: 20 | M14: 20 | O14: 80 | P14: =J14+N(K14)+N(L14)+N(M14)+N(O14)+N14 -> 200 | Q14: 0 | R14: =IF(Q14="","",N(Q14)-P14) -> -200
A15: 9 | B15: 3380TU 104 | D15: PLATEAU | I15: =$F$3 -> 2 | J15: =IF(OR(H15="",I15=""),0,H15*I15) -> 0 | K15: 80 | L15: 20 | M15: 20 | O15: 80 | P15: =J15+N(K15)+N(L15)+N(M15)+N(O15)+N15 -> 200 | Q15: 0 | R15: =IF(Q15="","",N(Q15)-P15) -> -200
A16: 10 | B16: 7243 TU 75 | C16: LASSAD AMRI | D16: PLATEAU | E16: OUDHREF | F16: 80 | H16: 30 | I16: =$F$3 -> 2 | J16: =IF(OR(H16="",I16=""),0,H16*I16) -> 60 | K16: 80 | L16: 20 | M16: 20 | O16: 80 | P16: =J16+N(K16)+N(L16)+N(M16)+N(O16)+N16 -> 260 | Q16: 200 | R16: =IF(Q16="","",N(Q16)-P16) -> -60
A17: 11 | B17: 4188 TU 80 | C17: SAMI | D17: PLATEAU | I17: =$F$3 -> 2 | J17: =IF(OR(H17="",I17=""),0,H17*I17) -> 0 | K17: 80 | L17: 20 | M17: 20 | O17: 80 | P17: =J17+N(K17)+N(L17)+N(M17)+N(O17)+N17 -> 200 | Q17: 0 | R17: =IF(Q17="","",N(Q17)-P17) -> -200
A18: 12 | B18: 2318 TU 155 | C18: KAMEL CH | D18: BENNE | E18: CHAGRA/ CHAGRA | F18: 200 | H18: 65 | I18: =$F$3 -> 2 | J18: =IF(OR(H18="",I18=""),0,H18*I18) -> 130 | K18: 80 | L18: 20 | M18: 20 | O18: 80 | P18: =J18+N(K18)+N(L18)+N(M18)+N(O18)+N18 -> 330 | Q18: 500 | R18: =IF(Q18="","",N(Q18)-P18) -> 170
A19: 13 | B19: 788 TU 99 | C19: KAMEL ZAY | D19: BENNE | I19: =$F$3 -> 2 | J19: =IF(OR(H19="",I19=""),0,H19*I19) -> 0 | K19: 80 | L19: 20 | M19: 20 | O19: 80 | P19: =J19+N(K19)+N(L19)+N(M19)+N(O19)+N19 -> 200 | Q19: 0 | R19: =IF(Q19="","",N(Q19)-P19) -> -200
A20: 14 | B20: 8564 TU 257 | C20: CHOKRI THAMER | D20: BENNE | E20: FAIEDH/SP/2SB | F20: 400 | H20: 135 | I20: =$F$3 -> 2 | J20: =IF(OR(H20="",I20=""),0,H20*I20) -> 270 | K20: 400 | L20: 32 | M20: 20 | O20: 80 | P20: =J20+N(K20)+N(L20)+N(M20)+N(O20)+N20 -> 802 | Q20: 980 | R20: =IF(Q20="","",N(Q20)-P20) -> 178
A21: 15 | B21: 8566 TU 257 | C21: HSAN REBII | D21: BENNE | E21: FAIEDH/SP/2SB | F21: 400 | H21: 135 | I21: =$F$3 -> 2 | J21: =IF(OR(H21="",I21=""),0,H21*I21) -> 270 | K21: 400 | L21: 32 | M21: 20 | O21: 80 | P21: =J21+N(K21)+N(L21)+N(M21)+N(O21)+N21 -> 802 | Q21: 980 | R21: =IF(Q21="","",N(Q21)-P21) -> 178
A22: 16 | I22: =$F$3 -> 2 | J22: =IF(OR(H22="",I22=""),0,H22*I22) -> 0 | L22: 0 | M22: 0 | O22: 0 | P22: =J22+N(K22)+N(L22)+N(M22)+N(O22)+N22 -> 0
A23: 17 | I23: =$F$3 -> 2 | J23: =IF(OR(H23="",I23=""),0,H23*I23) -> 0 | L23: 0 | M23: 0 | O23: 0 | P23: =J23+N(K23)+N(L23)+N(M23)+N(O23)+N23 -> 0 | R23: =IF(Q23="","",N(Q23)-P23)
A24: 18 | I24: =$F$3 -> 2 | J24: =IF(OR(H24="",I24=""),0,H24*I24) -> 0 | L24: 0 | M24: 0 | O24: 0 | P24: =J24+N(K24)+N(L24)+N(M24)+N(O24)+N24 -> 0 | R24: =IF(Q24="","",N(Q24)-P24)
A26: TOTAL JOUR | F26: =SUM(F7:F24) -> 5774 | H26: =SUM(H7:H24) -> 1810 | J26: =SUM(J7:J24) -> 3620 | K26: =SUM(K7:K21) -> 3120 | L26: =SUM(L7:L21) -> 360 | M26: =SUM(M7:M21) -> 300 | N26: =SUM(N7:N21) -> 1070 | O26: =SUM(O7:O21) -> 1200 | P26: =SUM(P7:P24) -> 9670 | Q26: =SUM(Q7:Q24) -> 7080 | R26: =SUM(R7:R24) -> -2590
F27: Total km jour | H27: Total gasoil (L) | J27: Total montant gasoil | K27: totale charge | L27: totale assurance | M27: totale taxe | N27: totale maint | O27: totale charge pers | P27: Total coûts | Q27: Total prix livraison | R27: Résultat global

Sheet 03-02-26
A1: TABLEAU DE SUIVI JOURNALIER — CAMIONS (PRODUIT FINI & MATIÈRE PREMIÈRE)
B2: *
A3: Date | C3: 46056 | D3: Prix gasoil / L (par défaut) | F3: 2 | G3: Devise | I3: TND
A4: Saisir les valeurs en bleu. Les colonnes Montant global gasoil, Coût total et Résultat se calculent automatiquement.
A6: N° | B6: Matricule camion | C6: Nom chauffeur | D6: Type transport | E6: Destination | F6: Kilométrage du jour (km) | G6: Kilométrage global (km) | H6: Quantité gasoil (L) | I6: Prix gasoil / L | J6: Montant global gasoil | K6: Charges fixes | L6: Montant assurance | M6: Montant taxe | N6: Maintenance | O6: Charge personnel | P6: Coût total | Q6: Prix livraison | R6: Résultat (livraison - coût) | S6: Remarques
A7: 1 | B7: 8565 TU 257 | C7: CHOKAIRI | D7: PLATEAU | F7: 0 | H7: 0 | I7: =$F$3 -> 2 | J7: =IF(OR(H7="",I7=""),0,H7*I7) -> 0 | K7: 400 | L7: 32 | M7: 20 | O7: 80 | P7: =J7+N(K7)+N(L7)+N(M7)+N(O7)+N7 -> 532 | Q7: 0 | R7: =IF(Q7="","",N(Q7)-P7) -> -532
A8: 2 | B8: 8563 TU 257 | C8: LASSAD CHATAOUI | D8: PLATEAU | E8: GAFSSA | F8: 300 | H8: 90 | I8: =$F$3 -> 2 | J8: =IF(OR(H8="",I8=""),0,H8*I8) -> 180 | K8: 400 | L8: 32 | M8: 20 | N8: 0 | O8: 80 | P8: =J8+N(K8)+N(L8)+N(M8)+N(O8)+N8 -> 712 | Q8: 600 | R8: =IF(Q8="","",N(Q8)-P8) -> -112
A9: 3 | B9: 5305 TU 236 | C9: HAMZA | D9: PLATEAU | E9: ZARZIS | F9: 414 | H9: 145 | I9: =$F$3 -> 2 | J9: =IF(OR(H9="",I9=""),0,H9*I9) -> 290 | K9: 80 | L9: 20 | M9: 20 | O9: 80 | P9: =J9+N(K9)+N(L9)+N(M9)+N(O9)+N9 -> 490 | Q9: 524 | R9: =IF(Q9="","",N(Q9)-P9) -> 34
A10: 4 | B10: 924 TU 98 | C10: IKRAMI | D10: PLATEAU | E10: DJERBA | F10: 380 | H10: 120 | I10: =$F$3 -> 2 | J10: =IF(OR(H10="",I10=""),0,H10*I10) -> 240 | K10: 80 | L10: 20 | M10: 20 | O10: 80 | P10: =J10+N(K10)+N(L10)+N(M10)+N(O10)+N10 -> 440 | Q10: 553 | R10: =IF(Q10="","",N(Q10)-P10) -> 113
A11: 5 | B11: 6980 TU 101 | C11: ABDELBARI | D11: PLATEAU | E11: ELHAMMA | F11: 180 | H11: 40 | I11: =$F$3 -> 2 | J11: =IF(OR(H11="",I11=""),0,H11*I11) -> 80 | K11: 80 | L11: 20 | M11: 20 | O11: 80 | P11: =J11+N(K11)+N(L11)+N(M11)+N(O11)+N11 -> 280 | Q11: 234 | R11: =IF(Q11="","",N(Q11)-P11) -> -46
A12: 6 | B12: 7775 TU 252 | C12: JAMIL | D12: PLATEAU | I12: =$F$3 -> 2 | J12: =IF(OR(H12="",I12=""),0,H12*I12) -> 0 | K12: 400 | L12: 20 | M12: 20 | O12: 80 | P12: =J12+N(K12)+N(L12)+N(M12)+N(O12)+N12 -> 520 | Q12: 1090 | R12: =IF(Q12="","",N(Q12)-P12) -> 570
A13: 7 | B13: 4176 TU 250 | C13: HEDI | D13: PLATEAU | I13: =$F$3 -> 2 | J13: =IF(OR(H13="",I13=""),0,H13*I13) -> 0 | K13: 400 | L13: 32 | M13: 20 | O13: 80 | P13: =J13+N(K13)+N(L13)+N(M13)+N(O13)+N13 -> 532 | Q13: 0 | R13: =IF(Q13="","",N(Q13)-P13) -> -532
A14: 8 | B14: 446 TU 228 | C14: MALEK | D14: PLATEAU | I14: =$F$3 -> 2 | J14: =IF(OR(H14="",I14=""),0,H14*I14) -> 0 | K14: 80 | L14: 20 | M14: 20 | O14: 80 | P14: =J14+N(K14)+N(L14)+N(M14)+N(O14)+N14 -> 200 | Q14: 0 | R14: =IF(Q14="","",N(Q14)-P14) -> -200
A15: 9 | B15: 3380TU 104 | D15: PLATEAU | I15: =$F$3 -> 2 | J15: =IF(OR(H15="",I15=""),0,H15*I15) -> 0 | K15: 80 | L15: 20 | M15: 20 | N15: 446.25 | O15: 80 | P15: =J15+N(K15)+N(L15)+N(M15)+N(O15)+N15 -> 646.25 | Q15: 0 | R15: =IF(Q15="","",N(Q15)-P15) -> -646.25
A16: 10 | B16: 7243 TU 75 | C16: LASSAD AMRI | D16: PLATEAU | E16: OUDHREF | F16: 80 | H16: 30 | I16: =$F$3 -> 2 | J16: =IF(OR(H16="",I16=""),0,H16*I16) -> 60 | K16: 80 | L16: 20 | M16: 20 | O16: 80 | P16: =J16+N(K16)+N(L16)+N(M16)+N(O16)+N16 -> 260 | Q16: 200 | R16: =IF(Q16="","",N(Q16)-P16) -> -60
A17: 11 | B17: 4188 TU 80 | C17: SAMI | D17: PLATEAU | I17: =$F$3 -> 2 | J17: =IF(OR(H17="",I17=""),0,H17*I17) -> 0 | K17: 80 | L17: 20 | M17: 20 | O17: 80 | P17: =J17+N(K17)+N(L17)+N(M17)+N(O17)+N17 -> 200 | Q17: 0 | R17: =IF(Q17="","",N(Q17)-P17) -> -200
A18: 12 | B18: 2318 TU 155 | C18: KAMEL CH | D18: BENNE | E18: CHAGRA/SB | F18: 320 | H18: 120 | I18: =$F$3 -> 2 | J18: =IF(OR(H18="",I18=""),0,H18*I18) -> 240 | K18: 80 | L18: 20 | M18: 20 | N18: 119 | O18: 80 | P18: =J18+N(K18)+N(L18)+N(M18)+N(O18)+N18 -> 559 | Q18: 800 | R18: =IF(Q18="","",N(Q18)-P18) -> 241
A19: 13 | B19: 788 TU 99 | C19: KAMEL ZAY | D19: BENNE | I19: =$F$3 -> 2 | J19: =IF(OR(H19="",I19=""),0,H19*I19) -> 0 | K19: 80 | L19: 20 | M19: 20 | O19: 80 | P19: =J19+N(K19)+N(L19)+N(M19)+N(O19)+N19 -> 200 | Q19: 0 | R19: =IF(Q19="","",N(Q19)-P19) -> -200
A20: 14 | B20: 8564 TU 257 | C20: CHOKRI THAMER | D20: BENNE | E20: FAIEDH/SP/2SB | F20: 300 | H20: 100 | I20: =$F$3 -> 2 | J20: =IF(OR(H20="",I20=""),0,H20*I20) -> 200 | K20: 400 | L20: 32 | M20: 20 | O20: 80 | P20: =J20+N(K20)+N(L20)+N(M20)+N(O20)+N20 -> 732 | Q20: 960 | R20: =IF(Q20="","",N(Q20)-P20) -> 228
A21: 15 | B21: 8566 TU 257 | C21: HSAN REBII | D21: BENNE | E21: FAIEDH/SP/2SB | F21: 300 | H21: 100 | I21: =$F$3 -> 2 | J21: =IF(OR(H21="",I21=""),0,H21*I21) -> 200 | K21: 400 | L21: 32 | M21: 20 | O21: 80 | P21: =J21+N(K21)+N(L21)+N(M21)+N(O21)+N21 -> 732 | Q21: 960 | R21: =IF(Q21="","",N(Q21)-P21) -> 228
A22: 16 | I22: =$F$3 -> 2 | J22: =IF(OR(H22="",I22=""),0,H22*I22) -> 0 | L22: 0 | M22: 0 | O22: 0 | P22: =J22+N(K22)+N(L22)+N(M22)+N(O22)+N22 -> 0
A23: 17 | I23: =$F$3 -> 2 | J23: =IF(OR(H23="",I23=""),0,H23*I23) -> 0 | L23: 0 | M23: 0 | O23: 0 | P23: =J23+N(K23)+N(L23)+N(M23)+N(O23)+N23 -> 0 | R23: =IF(Q23="","",N(Q23)-P23)
A24: 18 | I24: =$F$3 -> 2 | J24: =IF(OR(H24="",I24=""),0,H24*I24) -> 0 | L24: 0 | M24: 0 | O24: 0 | P24: =J24+N(K24)+N(L24)+N(M24)+N(O24)+N24 -> 0 | R24: =IF(Q24="","",N(Q24)-P24)
A26: TOTAL JOUR | F26: =SUM(F7:F24) -> 2274 | H26: =SUM(H7:H24) -> 745 | J26: =SUM(J7:J24) -> 1490 | K26: =SUM(K7:K21) -> 3120 | L26: =SUM(L7:L21) -> 360 | M26: =SUM(M7:M21) -> 300 | N26: =SUM(N7:N21) -> 565.25 | O26: =SUM(O7:O21) -> 1200 | P26: =SUM(P7:P24) -> 7035.25 | Q26: =SUM(Q7:Q24) -> 5921 | R26: =SUM(R7:R24) -> -1114.25
F27: Total km jour | H27: Total gasoil (L) | J27: Total montant gasoil | K27: totale charge | L27: totale assurance | M27: totale taxe | N27: totale maint | O27: totale charge pers | P27: Total coûts | Q27: Total prix livraison | R27: Résultat global

Sheet 04-02-26
A1: TABLEAU DE SUIVI JOURNALIER — CAMIONS (PRODUIT FINI & MATIÈRE PREMIÈRE)
B2: *
A3: Date | C3: 46057 | D3: Prix gasoil / L (par défaut) | F3: 2 | G3: Devise | I3: TND
A4: Saisir les valeurs en bleu. Les colonnes Montant global gasoil, Coût total et Résultat se calculent automatiquement.
A6: N° | B6: Matricule camion | C6: Nom chauffeur | D6: Type transport | E6: Destination | F6: Kilométrage du jour (km) | G6: Kilométrage global (km) | H6: Quantité gasoil (L) | I6: Prix gasoil / L | J6: Montant global gasoil | K6: Charges fixes | L6: Montant assurance | M6: Montant taxe | N6: Maintenance | O6: Charge personnel | P6: Coût total | Q6: Prix livraison | R6: Résultat (livraison - coût) | S6: Remarques
A7: 1 | B7: 8565 TU 257 | C7: CHOKAIRI | D7: PLATEAU | E7: ZARZIS | F7: 414 | H7: 125 | I7: =$F$3 -> 2 | J7: =IF(OR(H7="",I7=""),0,H7*I7) -> 250 | K7: 400 | L7: 32 | M7: 20 | O7: 80 | P7: =J7+N(K7)+N(L7)+N(M7)+N(O7)+N7 -> 782 | Q7: 524 | R7: =IF(Q7="","",N(Q7)-P7) -> -258
A8: 2 | B8: 8563 TU 257 | C8: LASSAD CHATAOUI | D8: PLATEAU | E8: TUNIS | F8: 414 | H8: 125 | I8: =$F$3 -> 2 | J8: =IF(OR(H8="",I8=""),0,H8*I8) -> 250 | K8: 400 | L8: 32 | M8: 20 | O8: 80 | P8: =J8+N(K8)+N(L8)+N(M8)+N(O8)+N8 -> 782 | Q8: 524 | R8: =IF(Q8="","",N(Q8)-P8) -> -258
A9: 3 | B9: 5305 TU 236 | C9: HAMZA | D9: PLATEAU | E9: OUDHREF | F9: 80 | H9: 30 | I9: =$F$3 -> 2 | J9: =IF(OR(H9="",I9=""),0,H9*I9) -> 60 | K9: 80 | L9: 20 | M9: 20 | O9: 80 | P9: =J9+N(K9)+N(L9)+N(M9)+N(O9)+N9 -> 260 | Q9: 187 | R9: =IF(Q9="","",N(Q9)-P9) -> -73
A10: 4 | B10: 924 TU 98 | C10: IKRAMI | D10: PLATEAU | E10: DJERBA | F10: 380 | H10: 120 | I10: =$F$3 -> 2 | J10: =IF(OR(H10="",I10=""),0,H10*I10) -> 240 | K10: 80 | L10: 20 | M10: 20 | N10: 1225.224 | O10: 80 | P10: =J10+N(K10)+N(L10)+N(M10)+N(O10)+N10 -> 1665.224 | Q10: 553 | R10: =IF(Q10="","",N(Q10)-P10) -> -1112.224
A11: 5 | B11: 6980 TU 101 | C11: ABDELBARI | D11: PLATEAU | E11: GABES | F11: 140 | H11: 40 | I11: =$F$3 -> 2 | J11: =IF(OR(H11="",I11=""),0,H11*I11) -> 80 | K11: 80 | L11: 20 | M11: 20 | N11: 420.957 | O11: 80 | P11: =J11+N(K11)+N(L11)+N(M11)+N(O11)+N11 -> 700.957 | Q11: 234 | R11: =IF(Q11="","",N(Q11)-P11) -> -466.957
A12: 6 | B12: 7775 TU 252 | C12: JAMIL | D12: PLATEAU | E12: MEHDIA/TUNIS | I12: =$F$3 -> 2 | J12: =IF(OR(H12="",I12=""),0,H12*I12) -> 0 | K12: 400 | L12: 20 | M12: 20 | O12: 80 | P12: =J12+N(K12)+N(L12)+N(M12)+N(O12)+N12 -> 520 | Q12: 0 | R12: =IF(Q12="","",N(Q12)-P12) -> -520
A13: 7 | B13: 4176 TU 250 | C13: HEDI | D13: PLATEAU | E13: BENGUERDENE | F13: 440 | H13: 140 | I13: =$F$3 -> 2 | J13: =IF(OR(H13="",I13=""),0,H13*I13) -> 280 | K13: 400 | L13: 32 | M13: 20 | O13: 80 | P13: =J13+N(K13)+N(L13)+N(M13)+N(O13)+N13 -> 812 | Q13: 670 | R13: =IF(Q13="","",N(Q13)-P13) -> -142
A14: 8 | B14: 446 TU 228 | C14: MALEK | D14: PLATEAU | I14: =$F$3 -> 2 | J14: =IF(OR(H14="",I14=""),0,H14*I14) -> 0 | K14: 80 | L14: 20 | M14: 20 | N14: 620 | O14: 80 | P14: =J14+N(K14)+N(L14)+N(M14)+N(O14)+N14 -> 820 | Q14: 0 | R14: =IF(Q14="","",N(Q14)-P14) -> -820
A15: 9 | B15: 3380TU 104 | D15: PLATEAU | E15: GABES | F15: 140 | H15: 40 | I15: =$F$3 -> 2 | J15: =IF(OR(H15="",I15=""),0,H15*I15) -> 80 | K15: 80 | L15: 20 | M15: 20 | O15: 80 | P15: =J15+N(K15)+N(L15)+N(M15)+N(O15)+N15 -> 280 | Q15: 234 | R15: =IF(Q15="","",N(Q15)-P15) -> -46
A16: 10 | B16: 7243 TU 75 | C16: LASSAD AMRI | D16: PLATEAU | E16: PARC | F16: 0 | H16: 0 | I16: =$F$3 -> 2 | J16: =IF(OR(H16="",I16=""),0,H16*I16) -> 0 | K16: 80 | L16: 20 | M16: 20 | O16: 80 | P16: =J16+N(K16)+N(L16)+N(M16)+N(O16)+N16 -> 200 | Q16: 0 | R16: =IF(Q16="","",N(Q16)-P16) -> -200
A17: 11 | B17: 4188 TU 80 | C17: SAMI | D17: PLATEAU | I17: =$F$3 -> 2 | J17: =IF(OR(H17="",I17=""),0,H17*I17) -> 0 | K17: 80 | L17: 20 | M17: 20 | N17: 673.659 | O17: 80 | P17: =J17+N(K17)+N(L17)+N(M17)+N(O17)+N17 -> 873.659 | Q17: 0 | R17: =IF(Q17="","",N(Q17)-P17) -> -873.659
A18: 12 | B18: 2318 TU 155 | C18: KAMEL CH | D18: BENNE | E18: CHAGRA/ SB | F18: 320 | H18: 120 | I18: =$F$3 -> 2 | J18: =IF(OR(H18="",I18=""),0,H18*I18) -> 240 | K18: 80 | L18: 20 | M18: 20 | O18: 80 | P18: =J18+N(K18)+N(L18)+N(M18)+N(O18)+N18 -> 440 | Q18: 800 | R18: =IF(Q18="","",N(Q18)-P18) -> 360
A19: 13 | B19: 788 TU 99 | C19: KAMEL ZAY | D19: BENNE | I19: =$F$3 -> 2 | J19: =IF(OR(H19="",I19=""),0,H19*I19) -> 0 | K19: 80 | L19: 20 | M19: 20 | O19: 80 | P19: =J19+N(K19)+N(L19)+N(M19)+N(O19)+N19 -> 200 | Q19: 0 | R19: =IF(Q19="","",N(Q19)-P19) -> -200
A20: 14 | B20: 8564 TU 257 | C20: CHOKRI THAMER | D20: BENNE | E20: FAIEDH/SP/2SB | F20: 400 | H20: 135 | I20: =$F$3 -> 2 | J20: =IF(OR(H20="",I20=""),0,H20*I20) -> 270 | K20: 400 | L20: 32 | M20: 20 | N20: 373.385 | O20: 80 | P20: =J20+N(K20)+N(L20)+N(M20)+N(O20)+N20 -> 1175.385 | Q20: 980 | R20: =IF(Q20="","",N(Q20)-P20) -> -195.385
A21: 15 | B21: 8566 TU 257 | C21: HSAN REBII | D21: BENNE | E21: FAIEDH/SP/2SB | F21: 400 | H21: 135 | I21: =$F$3 -> 2 | J21: =IF(OR(H21="",I21=""),0,H21*I21) -> 270 | K21: 400 | L21: 32 | M21: 20 | O21: 80 | P21: =J21+N(K21)+N(L21)+N(M21)+N(O21)+N21 -> 802 | Q21: 980 | R21: =IF(Q21="","",N(Q21)-P21) -> 178
A22: 16 | I22: =$F$3 -> 2 | J22: =IF(OR(H22="",I22=""),0,H22*I22) -> 0 | L22: 0 | M22: 0 | O22: 0 | P22: =J22+N(K22)+N(L22)+N(M22)+N(O22)+N22 -> 0
A23: 17 | I23: =$F$3 -> 2 | J23: =IF(OR(H23="",I23=""),0,H23*I23) -> 0 | L23: 0 | M23: 0 | O23: 0 | P23: =J23+N(K23)+N(L23)+N(M23)+N(O23)+N23 -> 0 | R23: =IF(Q23="","",N(Q23)-P23)
A24: 18 | I24: =$F$3 -> 2 | J24: =IF(OR(H24="",I24=""),0,H24*I24) -> 0 | L24: 0 | M24: 0 | O24: 0 | P24: =J24+N(K24)+N(L24)+N(M24)+N(O24)+N24 -> 0 | R24: =IF(Q24="","",N(Q24)-P24)
A26: TOTAL JOUR | F26: =SUM(F7:F24) -> 3128 | H26: =SUM(H7:H24) -> 1010 | J26: =SUM(J7:J24) -> 2020 | K26: =SUM(K7:K21) -> 3120 | L26: =SUM(L7:L21) -> 360 | M26: =SUM(M7:M21) -> 300 | N26: =SUM(N7:N21) -> 3313.225 | O26: =SUM(O7:O21) -> 1200 | P26: =SUM(P7:P24) -> 10313.225 | Q26: =SUM(Q7:Q24) -> 5686 | R26: =SUM(R7:R24) -> -4627.225
F27: Total km jour | H27: Total gasoil (L) | J27: Total montant gasoil | K27: totale charge | L27: totale assurance | M27: totale taxe | N27: totale maint | O27: totale charge pers | P27: Total coûts | Q27: Total prix livraison | R27: Résultat global

Sheet 05-02-26
A1: TABLEAU DE SUIVI JOURNALIER — CAMIONS (PRODUIT FINI & MATIÈRE PREMIÈRE)
B2: *
A3: Date | C3: 46058 | D3: Prix gasoil / L (par défaut) | F3: 2 | G3: Devise | I3: TND
A4: Saisir les valeurs en bleu. Les colonnes Montant global gasoil, Coût total et Résultat se calculent automatiquement.
A6: N° | B6: Matricule camion | C6: Nom chauffeur | D6: Type transport | E6: Destination | F6: Kilométrage du jour (km) | G6: Kilométrage global (km) | H6: Quantité gasoil (L) | I6: Prix gasoil / L | J6: Montant global gasoil | K6: Charges fixes | L6: Montant assurance | M6: Montant taxe | N6: Maintenance | O6: Charge personnel | P6: Coût total | Q6: Prix livraison | R6: Résultat (livraison - coût) | S6: Remarques
A7: 1 | B7: 8565 TU 257 | C7: CHOKAIRI | D7: PLATEAU | E7: GHANOUCH | F7: 130 | H7: 40 | I7: =$F$3 -> 2 | J7: =IF(OR(H7="",I7=""),0,H7*I7) -> 80 | K7: 400 | L7: 32 | M7: 20 | N7: 0 | O7: 80 | P7: =J7+N(K7)+N(L7)+N(M7)+N(O7)+N7 -> 612 | Q7: 234 | R7: =IF(Q7="","",N(Q7)-P7) -> -378
A8: 2 | B8: 8563 TU 257 | C8: LASSAD CHATAOUI | D8: PLATEAU | E8: DJERBA | F8: 380 | H8: 110 | I8: =$F$3 -> 2 | J8: =IF(OR(H8="",I8=""),0,H8*I8) -> 220 | K8: 400 | L8: 32 | M8: 20 | N8: 1066 | O8: 80 | P8: =J8+N(K8)+N(L8)+N(M8)+N(O8)+N8 -> 1818 | Q8: 591 | R8: =IF(Q8="","",N(Q8)-P8) -> -1227
A9: 3 | B9: 5305 TU 236 | C9: HAMZA | D9: PLATEAU | F9: 0 | H9: 0 | I9: =$F$3 -> 2 | J9: =IF(OR(H9="",I9=""),0,H9*I9) -> 0 | K9: 80 | L9: 20 | M9: 20 | N9: 0 | O9: 80 | P9: =J9+N(K9)+N(L9)+N(M9)+N(O9)+N9 -> 200 | Q9: 0 | R9: =IF(Q9="","",N(Q9)-P9) -> -200
A10: 4 | B10: 924 TU 98 | C10: IKRAMI | D10: PLATEAU | E10: DJERBA | F10: 380 | H10: 120 | I10: =$F$3 -> 2 | J10: =IF(OR(H10="",I10=""),0,H10*I10) -> 240 | K10: 80 | L10: 20 | M10: 20 | N10: 0 | O10: 80 | P10: =J10+N(K10)+N(L10)+N(M10)+N(O10)+N10 -> 440 | Q10: 591 | R10: =IF(Q10="","",N(Q10)-P10) -> 151
A11: 5 | B11: 6980 TU 101 | C11: ABDELBARI | D11: PLATEAU | F11: 0 | H11: 0 | I11: =$F$3 -> 2 | J11: =IF(OR(H11="",I11=""),0,H11*I11) -> 0 | K11: 80 | L11: 20 | M11: 20 | N11: 0 | O11: 80 | P11: =J11+N(K11)+N(L11)+N(M11)+N(O11)+N11 -> 200 | Q11: 0 | R11: =IF(Q11="","",N(Q11)-P11) -> -200
A12: 6 | B12: 7775 TU 252 | C12: JAMIL | D12: PLATEAU | E12: GABES/DJERBA | F12: 520 | H12: 160 | I12: =$F$3 -> 2 | J12: =IF(OR(H12="",I12=""),0,H12*I12) -> 320 | K12: 400 | L12: 20 | M12: 20 | N12: 0 | O12: 80 | P12: =J12+N(K12)+N(L12)+N(M12)+N(O12)+N12 -> 840 | Q12: 841 | R12: =IF(Q12="","",N(Q12)-P12) -> 1
A13: 7 | B13: 4176 TU 250 | C13: HEDI | D13: PLATEAU | E13: MAHDIA | F13: 450 | H13: 140 | I13: =$F$3 -> 2 | J13: =IF(OR(H13="",I13=""),0,H13*I13) -> 280 | K13: 400 | L13: 32 | M13: 20 | N13: 0 | O13: 80 | P13: =J13+N(K13)+N(L13)+N(M13)+N(O13)+N13 -> 812 | Q13: 590 | R13: =IF(Q13="","",N(Q13)-P13) -> -222 | S13: VIDANGE
A14: 8 | B14: 446 TU 228 | C14: MALEK | D14: PLATEAU | F14: 0 | H14: 0 | I14: =$F$3 -> 2 | J14: =IF(OR(H14="",I14=""),0,H14*I14) -> 0 | K14: 80 | L14: 20 | M14: 20 | N14: 0 | O14: 80 | P14: =J14+N(K14)+N(L14)+N(M14)+N(O14)+N14 -> 200 | Q14: 0 | R14: =IF(Q14="","",N(Q14)-P14) -> -200
A15: 9 | B15: 3380TU 104 | D15: PLATEAU | F15: 0 | H15: 0 | I15: =$F$3 -> 2 | J15: =IF(OR(H15="",I15=""),0,H15*I15) -> 0 | K15: 80 | L15: 20 | M15: 20 | N15: 0 | O15: 80 | P15: =J15+N(K15)+N(L15)+N(M15)+N(O15)+N15 -> 200 | Q15: 0 | R15: =IF(Q15="","",N(Q15)-P15) -> -200
A16: 10 | B16: 7243 TU 75 | C16: LASSAD AMRI | D16: PLATEAU | E16: OUDHREF | F16: 0 | H16: 0 | I16: =$F$3 -> 2 | J16: =IF(OR(H16="",I16=""),0,H16*I16) -> 0 | K16: 80 | L16: 20 | M16: 20 | N16: 0 | O16: 80 | P16: =J16+N(K16)+N(L16)+N(M16)+N(O16)+N16 -> 200 | Q16: 0 | R16: =IF(Q16="","",N(Q16)-P16) -> -200
A17: 11 | B17: 4188 TU 80 | C17: SAMI | D17: PLATEAU | F17: 0 | H17: 0 | I17: =$F$3 -> 2 | J17: =IF(OR(H17="",I17=""),0,H17*I17) -> 0 | K17: 80 | L17: 20 | M17: 20 | N17: 449.82 | O17: 80 | P17: =J17+N(K17)+N(L17)+N(M17)+N(O17)+N17 -> 649.82 | Q17: 0 | R17: =IF(Q17="","",N(Q17)-P17) -> -649.82
A18: 12 | B18: 2318 TU 155 | C18: KAMEL CH | D18: BENNE | E18: CHAGRA/ SB | F18: 320 | H18: 120 | I18: =$F$3 -> 2 | J18: =IF(OR(H18="",I18=""),0,H18*I18) -> 240 | K18: 80 | L18: 20 | M18: 20 | N18: 0 | O18: 80 | P18: =J18+N(K18)+N(L18)+N(M18)+N(O18)+N18 -> 440 | Q18: 800 | R18: =IF(Q18="","",N(Q18)-P18) -> 360
A19: 13 | B19: 788 TU 99 | C19: KAMEL ZAY | D19: BENNE | F19: 0 | H19: 0 | I19: =$F$3 -> 2 | J19: =IF(OR(H19="",I19=""),0,H19*I19) -> 0 | K19: 80 | L19: 20 | M19: 20 | N19: 0 | O19: 80 | P19: =J19+N(K19)+N(L19)+N(M19)+N(O19)+N19 -> 200 | Q19: 0 | R19: =IF(Q19="","",N(Q19)-P19) -> -200
A20: 14 | B20: 8564 TU 257 | C20: CHOKRI THAMER | D20: BENNE | E20: SUDB/SB/HICHA/SP | F20: 200 | H20: 60 | I20: =$F$3 -> 2 | J20: =IF(OR(H20="",I20=""),0,H20*I20) -> 120 | K20: 400 | L20: 32 | M20: 20 | N20: 0 | O20: 80 | P20: =J20+N(K20)+N(L20)+N(M20)+N(O20)+N20 -> 652 | Q20: 800 | R20: =IF(Q20="","",N(Q20)-P20) -> 148
A21: 15 | B21: 8566 TU 257 | C21: HSAN REBII | D21: BENNE | E21: FAYEDH/FAYEDH | F21: 300 | H21: 100 | I21: =$F$3 -> 2 | J21: =IF(OR(H21="",I21=""),0,H21*I21) -> 200 | K21: 400 | L21: 32 | M21: 20 | N21: 0 | O21: 80 | P21: =J21+N(K21)+N(L21)+N(M21)+N(O21)+N21 -> 732 | Q21: 960 | R21: =IF(Q21="","",N(Q21)-P21) -> 228
A22: 16 | I22: =$F$3 -> 2 | J22: =IF(OR(H22="",I22=""),0,H22*I22) -> 0 | L22: 0 | M22: 0 | N22: 0 | O22: 0 | P22: =J22+N(K22)+N(L22)+N(M22)+N(O22)+N22 -> 0 | Q22: 0 | R22: =IF(Q22="","",N(Q22)-P22) -> 0
A23: 17 | I23: =$F$3 -> 2 | J23: =IF(OR(H23="",I23=""),0,H23*I23) -> 0 | L23: 0 | M23: 0 | N23: 0 | O23: 0 | P23: =J23+N(K23)+N(L23)+N(M23)+N(O23)+N23 -> 0 | Q23: 0 | R23: =IF(Q23="","",N(Q23)-P23) -> 0
A24: 18 | I24: =$F$3 -> 2 | J24: =IF(OR(H24="",I24=""),0,H24*I24) -> 0 | L24: 0 | M24: 0 | O24: 0 | P24: =J24+N(K24)+N(L24)+N(M24)+N(O24)+N24 -> 0 | R24: =IF(Q24="","",N(Q24)-P24)
A26: TOTAL JOUR | F26: =SUM(F7:F24) -> 2680 | H26: =SUM(H7:H24) -> 850 | J26: =SUM(J7:J24) -> 1700 | K26: =SUM(K7:K21) -> 3120 | L26: =SUM(L7:L21) -> 360 | M26: =SUM(M7:M21) -> 300 | N26: =SUM(N7:N23) -> 1515.82 | O26: =SUM(O7:O21) -> 1200 | P26: =SUM(P7:P24) -> 8195.82 | Q26: =SUM(Q7:Q24) -> 5407 | R26: =SUM(R7:R24) -> -2788.82
F27: Total km jour | H27: Total gasoil (L) | J27: Total montant gasoil | K27: totale charge | L27: totale assurance | M27: totale taxe | N27: totale maint | O27: totale charge pers | P27: Total coûts | Q27: Total prix livraison | R27: Résultat global

Sheet 06-02-26
A1: TABLEAU DE SUIVI JOURNALIER — CAMIONS (PRODUIT FINI & MATIÈRE PREMIÈRE)
B2: *
A3: Date | C3: 46059 | D3: Prix gasoil / L (par défaut) | F3: 2 | G3: Devise | I3: TND
A4: Saisir les valeurs en bleu. Les colonnes Montant global gasoil, Coût total et Résultat se calculent automatiquement.
A6: N° | B6: Matricule camion | C6: Nom chauffeur | D6: Type transport | E6: Destination | F6: Kilométrage du jour (km) | G6: Kilométrage global (km) | H6: Quantité gasoil (L) | I6: Prix gasoil / L | J6: Montant global gasoil | K6: Charges fixes | L6: Montant assurance | M6: Montant taxe | N6: Maintenance | O6: Charge personnel | P6: Coût total | Q6: Prix livraison | R6: Résultat (livraison - coût) | S6: Remarques
A7: 1 | B7: 8565 TU 257 | C7: CHOKAIRI | D7: PLATEAU | F7: 0 | H7: 0 | I7: =$F$3 -> 2 | J7: =IF(OR(H7="",I7=""),0,H7*I7) -> 0 | K7: 400 | L7: 32 | M7: 20 | N7: 0 | O7: 80 | P7: =J7+N(K7)+N(L7)+N(M7)+N(O7)+N7 -> 532 | Q7: 0 | R7: =IF(Q7="","",N(Q7)-P7) -> -532
A8: 2 | B8: 8563 TU 257 | C8: LASSAD CHATAOUI | D8: PLATEAU | E8: KAIROUAN/METOUIA | F8: 460 | H8: 135 | I8: =$F$3 -> 2 | J8: =IF(OR(H8="",I8=""),0,H8*I8) -> 270 | K8: 400 | L8: 32 | M8: 20 | N8: 0 | O8: 80 | P8: =J8+N(K8)+N(L8)+N(M8)+N(O8)+N8 -> 802 | Q8: 800 | R8: =IF(Q8="","",N(Q8)-P8) -> -2
A9: 3 | B9: 5305 TU 236 | C9: HAMZA | D9: PLATEAU | F9: 0 | H9: 0 | I9: =$F$3 -> 2 | J9: =IF(OR(H9="",I9=""),0,H9*I9) -> 0 | K9: 80 | L9: 20 | M9: 20 | N9: 0 | O9: 80 | P9: =J9+N(K9)+N(L9)+N(M9)+N(O9)+N9 -> 200 | Q9: 0 | R9: =IF(Q9="","",N(Q9)-P9) -> -200
A10: 4 | B10: 924 TU 98 | C10: IKRAMI | D10: PLATEAU | F10: 0 | H10: 0 | I10: =$F$3 -> 2 | J10: =IF(OR(H10="",I10=""),0,H10*I10) -> 0 | K10: 80 | L10: 20 | M10: 20 | N10: 0 | O10: 80 | P10: =J10+N(K10)+N(L10)+N(M10)+N(O10)+N10 -> 200 | Q10: 0 | R10: =IF(Q10="","",N(Q10)-P10) -> -200
A11: 5 | B11: 6980 TU 101 | C11: ABDELBARI | D11: PLATEAU | E11: KEBILI | F11: 390 | H11: 150 | I11: =$F$3 -> 2 | J11: =IF(OR(H11="",I11=""),0,H11*I11) -> 300 | K11: 80 | L11: 20 | M11: 20 | N11: 0 | O11: 80 | P11: =J11+N(K11)+N(L11)+N(M11)+N(O11)+N11 -> 500 | Q11: 650 | R11: =IF(Q11="","",N(Q11)-P11) -> 150
A12: 6 | B12: 7775 TU 252 | C12: JAMIL | D12: PLATEAU | E12: BENGUERDEN | F12: 440 | H12: 130 | I12: =$F$3 -> 2 | J12: =IF(OR(H12="",I12=""),0,H12*I12) -> 260 | K12: 400 | L12: 20 | M12: 20 | N12: 0 | O12: 80 | P12: =J12+N(K12)+N(L12)+N(M12)+N(O12)+N12 -> 780 | Q12: 670 | R12: =IF(Q12="","",N(Q12)-P12) -> -110
A13: 7 | B13: 4176 TU 250 | C13: HEDI | D13: PLATEAU | E13: MEHDIA/MAZOUNA | F13: 400 | H13: 125 | I13: =$F$3 -> 2 | J13: =IF(OR(H13="",I13=""),0,H13*I13) -> 250 | K13: 400 | L13: 32 | M13: 20 | N13: 0 | O13: 80 | P13: =J13+N(K13)+N(L13)+N(M13)+N(O13)+N13 -> 782 | Q13: 860 | R13: =IF(Q13="","",N(Q13)-P13) -> 78
A14: 8 | B14: 446 TU 228 | C14: MALEK | D14: PLATEAU | F14: 0 | H14: 0 | I14: =$F$3 -> 2 | J14: =IF(OR(H14="",I14=""),0,H14*I14) -> 0 | K14: 80 | L14: 20 | M14: 20 | N14: 0 | O14: 80 | P14: =J14+N(K14)+N(L14)+N(M14)+N(O14)+N14 -> 200 | Q14: 0 | R14: =IF(Q14="","",N(Q14)-P14) -> -200
A15: 9 | B15: 3380TU 104 | D15: PLATEAU | E15: MAZOUNA | F15: 120 | H15: 40 | I15: =$F$3 -> 2 | J15: =IF(OR(H15="",I15=""),0,H15*I15) -> 80 | K15: 80 | L15: 20 | M15: 20 | N15: 0 | O15: 80 | P15: =J15+N(K15)+N(L15)+N(M15)+N(O15)+N15 -> 280 | Q15: 310 | R15: =IF(Q15="","",N(Q15)-P15) -> 30
A16: 10 | B16: 7243 TU 75 | C16: LASSAD AMRI | D16: PLATEAU | F16: 0 | H16: 0 | I16: =$F$3 -> 2 | J16: =IF(OR(H16="",I16=""),0,H16*I16) -> 0 | K16: 80 | L16: 20 | M16: 20 | N16: 0 | O16: 80 | P16: =J16+N(K16)+N(L16)+N(M16)+N(O16)+N16 -> 200 | Q16: 0 | R16: =IF(Q16="","",N(Q16)-P16) -> -200
A17: 11 | B17: 4188 TU 80 | C17: SAMI | D17: PLATEAU | F17: 0 | H17: 0 | I17: =$F$3 -> 2 | J17: =IF(OR(H17="",I17=""),0,H17*I17) -> 0 | K17: 80 | L17: 20 | M17: 20 | N17: 0 | O17: 80 | P17: =J17+N(K17)+N(L17)+N(M17)+N(O17)+N17 -> 200 | Q17: 0 | R17: =IF(Q17="","",N(Q17)-P17) -> -200
A18: 12 | B18: 2318 TU 155 | C18: KAMEL CH | D18: BENNE | E18: CH/SP-HICH/SB | F18: 220 | H18: 85 | I18: =$F$3 -> 2 | J18: =IF(OR(H18="",I18=""),0,H18*I18) -> 170 | K18: 80 | L18: 20 | M18: 20 | N18: 0 | O18: 80 | P18: =J18+N(K18)+N(L18)+N(M18)+N(O18)+N18 -> 370 | Q18: 820 | R18: =IF(Q18="","",N(Q18)-P18) -> 450
A19: 13 | B19: 788 TU 99 | C19: KAMEL ZAY | D19: BENNE | E19: SB-SP | F19: 100 | H19: 35 | I19: =$F$3 -> 2 | J19: =IF(OR(H19="",I19=""),0,H19*I19) -> 70 | K19: 80 | L19: 20 | M19: 20 | N19: 0 | O19: 80 | P19: =J19+N(K19)+N(L19)+N(M19)+N(O19)+N19 -> 270 | Q19: 200 | R19: =IF(Q19="","",N(Q19)-P19) -> -70
A20: 14 | B20: 8564 TU 257 | C20: CHOKRI THAMER | D20: BENNE | E20: FAIEDH/SB/SP/HICH/SB | F20: 400 | H20: 135 | I20: =$F$3 -> 2 | J20: =IF(OR(H20="",I20=""),0,H20*I20) -> 270 | K20: 400 | L20: 32 | M20: 20 | N20: 0 | O20: 80 | P20: =J20+N(K20)+N(L20)+N(M20)+N(O20)+N20 -> 802 | Q20: 1020 | R20: =IF(Q20="","",N(Q20)-P20) -> 218
A21: 15 | B21: 8566 TU 257 | C21: HSAN REBII | D21: BENNE | E21: FAIEDH/SB/SP/HICH/SB | F21: 400 | H21: 135 | I21: =$F$3 -> 2 | J21: =IF(OR(H21="",I21=""),0,H21*I21) -> 270 | K21: 400 | L21: 32 | M21: 20 | N21: 0 | O21: 80 | P21: =J21+N(K21)+N(L21)+N(M21)+N(O21)+N21 -> 802 | Q21: 1020 | R21: =IF(Q21="","",N(Q21)-P21) -> 218
A22: 16 | I22: =$F$3 -> 2 | J22: =IF(OR(H22="",I22=""),0,H22*I22) -> 0 | L22: 0 | M22: 0 | N22: 0 | O22: 0 | P22: =J22+N(K22)+N(L22)+N(M22)+N(O22)+N22 -> 0 | Q22: 0 | R22: =IF(Q22="","",N(Q22)-P22) -> 0
A23: 17 | I23: =$F$3 -> 2 | J23: =IF(OR(H23="",I23=""),0,H23*I23) -> 0 | L23: 0 | M23: 0 | N23: 0 | O23: 0 | P23: =J23+N(K23)+N(L23)+N(M23)+N(O23)+N23 -> 0 | Q23: 0 | R23: =IF(Q23="","",N(Q23)-P23) -> 0
A24: 18 | I24: =$F$3 -> 2 | J24: =IF(OR(H24="",I24=""),0,H24*I24) -> 0 | L24: 0 | M24: 0 | O24: 0 | P24: =J24+N(K24)+N(L24)+N(M24)+N(O24)+N24 -> 0 | R24: =IF(Q24="","",N(Q24)-P24)
A26: TOTAL JOUR | F26: =SUM(F7:F24) -> 2930 | H26: =SUM(H7:H24) -> 970 | J26: =SUM(J7:J24) -> 1940 | K26: =SUM(K7:K21) -> 3120 | L26: =SUM(L7:L21) -> 360 | M26: =SUM(M7:M21) -> 300 | N26: =SUM(N7:N23) -> 0 | O26: =SUM(O7:O21) -> 1200 | P26: =SUM(P7:P24) -> 6920 | Q26: =SUM(Q7:Q24) -> 6350 | R26: =SUM(R7:R24) -> -570
F27: Total km jour | H27: Total gasoil (L) | J27: Total montant gasoil | K27: totale charge | L27: totale assurance | M27: totale taxe | N27: totale maint | O27: totale charge pers | P27: Total coûts | Q27: Total prix livraison | R27: Résultat global

Sheet 07-02-26 
A1: TABLEAU DE SUIVI JOURNALIER — CAMIONS (PRODUIT FINI & MATIÈRE PREMIÈRE)
B2: *
A3: Date | C3: 46060 | D3: Prix gasoil / L (par défaut) | F3: 2 | G3: Devise | I3: TND
A4: Saisir les valeurs en bleu. Les colonnes Montant global gasoil, Coût total et Résultat se calculent automatiquement.
A6: N° | B6: Matricule camion | C6: Nom chauffeur | D6: Type transport | E6: Destination | F6: Kilométrage du jour (km) | G6: Kilométrage global (km) | H6: Quantité gasoil (L) | I6: Prix gasoil / L | J6: Montant global gasoil | K6: Charges fixes | L6: Montant assurance | M6: Montant taxe | N6: Maintenance | O6: Charge personnel | P6: Coût total | Q6: Prix livraison | R6: Résultat (livraison - coût) | S6: Remarques
A7: 1 | B7: 8565 TU 257 | C7: CHOKAIRI | D7: PLATEAU | E7: Djerba | F7: 340 | H7: 110 | I7: =$F$3 -> 2 | J7: =IF(OR(H7="",I7=""),0,H7*I7) -> 220 | K7: 400 | L7: 32 | M7: 20 | N7: 0 | O7: 80 | P7: =J7+N(K7)+N(L7)+N(M7)+N(O7)+N7 -> 752 | Q7: 553 | R7: =IF(Q7="","",N(Q7)-P7) -> -199
A8: 2 | B8: 8563 TU 257 | C8: LASSAD CHATAOUI | D8: PLATEAU | E8: zerziz | F8: 380 | H8: 120 | I8: =$F$3 -> 2 | J8: =IF(OR(H8="",I8=""),0,H8*I8) -> 240 | K8: 400 | L8: 32 | M8: 20 | N8: 0 | O8: 80 | P8: =J8+N(K8)+N(L8)+N(M8)+N(O8)+N8 -> 772 | Q8: 560 | R8: =IF(Q8="","",N(Q8)-P8) -> -212
A9: 3 | B9: 5305 TU 236 | C9: HAMZA | D9: PLATEAU | E9: tunis | F9: 800 | H9: 240 | I9: =$F$3 -> 2 | J9: =IF(OR(H9="",I9=""),0,H9*I9) -> 480 | K9: 80 | L9: 20 | M9: 20 | N9: 0 | O9: 80 | P9: =J9+N(K9)+N(L9)+N(M9)+N(O9)+N9 -> 680 | Q9: 500 | R9: =IF(Q9="","",N(Q9)-P9) -> -180
A10: 4 | B10: 924 TU 98 | C10: IKRAMI | D10: PLATEAU | E10: DJERBA | F10: 340 | H10: 130 | I10: =$F$3 -> 2 | J10: =IF(OR(H10="",I10=""),0,H10*I10) -> 260 | K10: 80 | L10: 20 | M10: 20 | N10: 0 | O10: 80 | P10: =J10+N(K10)+N(L10)+N(M10)+N(O10)+N10 -> 460 | Q10: 591 | R10: =IF(Q10="","",N(Q10)-P10) -> 131
A11: 5 | B11: 6980 TU 101 | C11: ABDELBARI | D11: PLATEAU | E11: Zerziz/jerba | F11: 714 | H11: 245 | I11: =$F$3 -> 2 | J11: =IF(OR(H11="",I11=""),0,H11*I11) -> 490 | K11: 80 | L11: 20 | M11: 20 | N11: 0 | O11: 80 | P11: =J11+N(K11)+N(L11)+N(M11)+N(O11)+N11 -> 690 | Q11: 1113 | R11: =IF(Q11="","",N(Q11)-P11) -> 423
A12: 6 | B12: 7775 TU 252 | C12: JAMIL | D12: PLATEAU | E12: Djerba | F12: 340 | H12: 110 | I12: =$F$3 -> 2 | J12: =IF(OR(H12="",I12=""),0,H12*I12) -> 220 | K12: 400 | L12: 20 | M12: 20 | N12: 0 | O12: 80 | P12: =J12+N(K12)+N(L12)+N(M12)+N(O12)+N12 -> 740 | Q12: 650 | R12: =IF(Q12="","",N(Q12)-P12) -> -90
A13: 7 | B13: 4176 TU 250 | C13: HEDI | D13: PLATEAU | E13: souk lahad gbelli | F13: 400 | H13: 130 | I13: =$F$3 -> 2 | J13: =IF(OR(H13="",I13=""),0,H13*I13) -> 260 | K13: 400 | L13: 32 | M13: 20 | N13: 1545.11 | O13: 80 | P13: =J13+N(K13)+N(L13)+N(M13)+N(O13)+N13 -> 2337.11 | Q13: 650 | R13: =IF(Q13="","",N(Q13)-P13) -> -1687.11
A14: 8 | B14: 446TU228 | C14: MALEK | D14: PLATEAU | E14: ghannouch | F14: 100 | H14: 33 | I14: =$F$3 -> 2 | J14: =IF(OR(H14="",I14=""),0,H14*I14) -> 66 | K14: 80 | L14: 20 | M14: 20 | N14: 0 | O14: 80 | P14: =J14+N(K14)+N(L14)+N(M14)+N(O14)+N14 -> 266 | Q14: 234 | R14: =IF(Q14="","",N(Q14)-P14) -> -32
A15: 9 | B15: 3380TU 104 | D15: PLATEAU | F15: 0 | H15: 0 | I15: =$F$3 -> 2 | J15: =IF(OR(H15="",I15=""),0,H15*I15) -> 0 | K15: 80 | L15: 20 | M15: 20 | N15: 0 | O15: 80 | P15: =J15+N(K15)+N(L15)+N(M15)+N(O15)+N15 -> 200 | Q15: 0 | R15: =IF(Q15="","",N(Q15)-P15) -> -200
A16: 10 | B16: 7243 TU 75 | C16: LASSAD AMRI | D16: PLATEAU | E16: OUDHREF | F16: 0 | H16: 0 | I16: =$F$3 -> 2 | J16: =IF(OR(H16="",I16=""),0,H16*I16) -> 0 | K16: 80 | L16: 20 | M16: 20 | N16: 0 | O16: 80 | P16: =J16+N(K16)+N(L16)+N(M16)+N(O16)+N16 -> 200 | Q16: 0 | R16: =IF(Q16="","",N(Q16)-P16) -> -200
A17: 11 | B17: 4188 TU 80 | C17: SAMI | D17: PLATEAU | E17: skhira/gabes | F17: 110 | H17: 35 | I17: =$F$3 -> 2 | J17: =IF(OR(H17="",I17=""),0,H17*I17) -> 70 | K17: 80 | L17: 20 | M17: 20 | N17: 0 | O17: 80 | P17: =J17+N(K17)+N(L17)+N(M17)+N(O17)+N17 -> 270 | Q17: 226 | R17: =IF(Q17="","",N(Q17)-P17) -> -44
A18: 12 | B18: 2318 TU 155 | C18: KAMEL CH | D18: BENNE | E18: CHAGRA/ sirep prefa Hicha/sirep beton | F18: 200 | H18: 80 | I18: =$F$3 -> 2 | J18: =IF(OR(H18="",I18=""),0,H18*I18) -> 160 | K18: 80 | L18: 20 | M18: 20 | N18: 0 | O18: 80 | P18: =J18+N(K18)+N(L18)+N(M18)+N(O18)+N18 -> 360 | Q18: 800 | R18: =IF(Q18="","",N(Q18)-P18) -> 440
A19: 13 | B19: 788 TU 99 | C19: KAMEL ZAY | D19: BENNE | F19: 0 | H19: 0 | I19: =$F$3 -> 2 | J19: =IF(OR(H19="",I19=""),0,H19*I19) -> 0 | K19: 80 | L19: 20 | M19: 20 | N19: 594 | O19: 80 | P19: =J19+N(K19)+N(L19)+N(M19)+N(O19)+N19 -> 794 | Q19: 0 | R19: =IF(Q19="","",N(Q19)-P19) -> -794
A20: 14 | B20: 8564 TU 257 | C20: CHOKRI THAMER | D20: BENNE | E20: sirep prefa/feidh | F20: 480 | H20: 150 | I20: =$F$3 -> 2 | J20: =IF(OR(H20="",I20=""),0,H20*I20) -> 300 | K20: 400 | L20: 32 | M20: 20 | N20: 0 | O20: 80 | P20: =J20+N(K20)+N(L20)+N(M20)+N(O20)+N20 -> 832 | Q20: 1095 | R20: =IF(Q20="","",N(Q20)-P20) -> 263
A21: 15 | B21: 8566 TU 257 | C21: HSAN REBII | D21: BENNE | E21: sirep prefa/feidh | F21: 480 | H21: 150 | I21: =$F$3 -> 2 | J21: =IF(OR(H21="",I21=""),0,H21*I21) -> 300 | K21: 400 | L21: 32 | M21: 20 | N21: 0 | O21: 80 | P21: =J21+N(K21)+N(L21)+N(M21)+N(O21)+N21 -> 832 | Q21: 1090 | R21: =IF(Q21="","",N(Q21)-P21) -> 258
A22: 16 | I22: =$F$3 -> 2 | J22: =IF(OR(H22="",I22=""),0,H22*I22) -> 0 | L22: 0 | M22: 0 | N22: 0 | O22: 0 | P22: =J22+N(K22)+N(L22)+N(M22)+N(O22)+N22 -> 0 | Q22: 0 | R22: =IF(Q22="","",N(Q22)-P22) -> 0
A23: 17 | I23: =$F$3 -> 2 | J23: =IF(OR(H23="",I23=""),0,H23*I23) -> 0 | L23: 0 | M23: 0 | N23: 0 | O23: 0 | P23: =J23+N(K23)+N(L23)+N(M23)+N(O23)+N23 -> 0 | Q23: 0 | R23: =IF(Q23="","",N(Q23)-P23) -> 0
A24: 18 | I24: =$F$3 -> 2 | J24: =IF(OR(H24="",I24=""),0,H24*I24) -> 0 | L24: 0 | M24: 0 | O24: 0 | P24: =J24+N(K24)+N(L24)+N(M24)+N(O24)+N24 -> 0 | R24: =IF(Q24="","",N(Q24)-P24)
A26: TOTAL JOUR | F26: =SUM(F7:F24) -> 4684 | H26: =SUM(H7:H24) -> 1533 | J26: =SUM(J7:J24) -> 3066 | K26: =SUM(K7:K21) -> 3120 | L26: =SUM(L7:L21) -> 360 | M26: =SUM(M7:M21) -> 300 | N26: =SUM(N7:N23) -> 2139.11 | O26: =SUM(O7:O21) -> 1200 | P26: =SUM(P7:P24) -> 10185.11 | Q26: =SUM(Q7:Q24) -> 8062 | R26: =SUM(R7:R24) -> -2123.11
F27: Total km jour | H27: Total gasoil (L) | J27: Total montant gasoil | K27: totale charge | L27: totale assurance | M27: totale taxe | N27: totale maint | O27: totale charge pers | P27: Total coûts | Q27: Total prix livraison | R27: Résultat global

Sheet 09-02-26
A1: TABLEAU DE SUIVI JOURNALIER — CAMIONS (PRODUIT FINI & MATIÈRE PREMIÈRE)
B2: *
A3: Date | C3: 46062 | D3: Prix gasoil / L (par défaut) | F3: 2 | G3: Devise | I3: TND
A4: Saisir les valeurs en bleu. Les colonnes Montant global gasoil, Coût total et Résultat se calculent automatiquement.
A6: N° | B6: Matricule camion | C6: Nom chauffeur | D6: Type transport | E6: Destination | F6: Kilométrage du jour (km) | G6: Kilométrage global (km) | H6: Quantité gasoil (L) | I6: Prix gasoil / L | J6: Montant global gasoil | K6: Charges fixes | L6: Montant assurance | M6: Montant taxe | N6: Maintenance | O6: Charge personnel | P6: Coût total | Q6: Prix livraison | R6: Résultat (livraison - coût) | S6: Remarques
A7: 1 | B7: 8565 TU 257 | C7: CHOKAIRI | D7: PLATEAU | E7: SKHIRA | F7: 10 | H7: 5 | I7: 2 | J7: =IF(OR(H7="",I7=""),0,H7*I7) -> 10 | K7: 400 | L7: 32 | M7: 20 | N7: 0 | O7: 80 | P7: =J7+N(K7)+N(L7)+N(M7)+N(O7)+N7 -> 542 | Q7: 150 | R7: =IF(Q7="","",N(Q7)-P7) -> -392
A8: 2 | B8: 8563 TU 257 | C8: LASSAD CHATAOUI | D8: PLATEAU | E8: SP/T,SOUDE | F8: 250 | H8: 100 | I8: 2 | J8: =IF(OR(H8="",I8=""),0,H8*I8) -> 200 | K8: 400 | L8: 32 | M8: 20 | N8: 0 | O8: 80 | P8: =J8+N(K8)+N(L8)+N(M8)+N(O8)+N8 -> 732 | Q8: 950 | R8: =IF(Q8="","",N(Q8)-P8) -> 218 | S8: Retour T.Soudé
A9: 3 | B9: 5305 TU 236 | C9: HAMZA | D9: PLATEAU | F9: 0 | H9: 0 | I9: =$F$3 -> 2 | J9: =IF(OR(H9="",I9=""),0,H9*I9) -> 0 | K9: 80 | L9: 20 | M9: 20 | N9: 0 | O9: 80 | P9: =J9+N(K9)+N(L9)+N(M9)+N(O9)+N9 -> 200 | Q9: 0 | R9: =IF(Q9="","",N(Q9)-P9) -> -200 | S9: Tunis
A10: 4 | B10: 924 TU 98 | C10: IKRAMI | D10: PLATEAU | E10: SKHIRA | F10: 10 | H10: 5 | I10: =$F$3 -> 2 | J10: =IF(OR(H10="",I10=""),0,H10*I10) -> 10 | K10: 80 | L10: 20 | M10: 20 | N10: 0 | O10: 80 | P10: =J10+N(K10)+N(L10)+N(M10)+N(O10)+N10 -> 210 | Q10: 150 | R10: =IF(Q10="","",N(Q10)-P10) -> -60
A11: 5 | B11: 6980 TU 101 | C11: ABDELBARI | D11: PLATEAU | E11: BEN GUERDENE | F11: 480 | H11: 200 | I11: =$F$3 -> 2 | J11: =IF(OR(H11="",I11=""),0,H11*I11) -> 400 | K11: 80 | L11: 20 | M11: 20 | N11: 0 | O11: 80 | P11: =J11+N(K11)+N(L11)+N(M11)+N(O11)+N11 -> 600 | Q11: 870 | R11: =IF(Q11="","",N(Q11)-P11) -> 270 | S11: Voyage fer de oudhref
A12: 6 | B12: 7775 TU 252 | C12: JAMIL | D12: PLATEAU | E12: DJERBA | F12: 350 | H12: 110 | I12: =$F$3 -> 2 | J12: =IF(OR(H12="",I12=""),0,H12*I12) -> 220 | K12: 400 | L12: 20 | M12: 20 | N12: 0 | O12: 80 | P12: =J12+N(K12)+N(L12)+N(M12)+N(O12)+N12 -> 740 | Q12: 591 | R12: =IF(Q12="","",N(Q12)-P12) -> -149
A13: 7 | B13: 4176 TU 250 | C13: HEDI | D13: PLATEAU | E13: DJERBA | F13: 350 | H13: 110 | I13: =$F$3 -> 2 | J13: =IF(OR(H13="",I13=""),0,H13*I13) -> 220 | K13: 400 | L13: 32 | M13: 20 | N13: 0 | O13: 80 | P13: =J13+N(K13)+N(L13)+N(M13)+N(O13)+N13 -> 752 | Q13: 591 | R13: =IF(Q13="","",N(Q13)-P13) -> -161
A14: 8 | B14: 446 TU 228 | C14: MALEK | D14: PLATEAU | E14: OUDHREF | F14: 80 | H14: 30 | I14: =$F$3 -> 2 | J14: =IF(OR(H14="",I14=""),0,H14*I14) -> 60 | K14: 80 | L14: 20 | M14: 20 | N14: 0 | O14: 80 | P14: =J14+N(K14)+N(L14)+N(M14)+N(O14)+N14 -> 260 | Q14: 200 | R14: =IF(Q14="","",N(Q14)-P14) -> -60 | S14: Voyage fer dsp
A15: 9 | B15: 3380 TU 104 | D15: PLATEAU | F15: 0 | H15: 0 | I15: =$F$3 -> 2 | J15: =IF(OR(H15="",I15=""),0,H15*I15) -> 0 | K15: 80 | L15: 20 | M15: 20 | N15: 0 | O15: 80 | P15: =J15+N(K15)+N(L15)+N(M15)+N(O15)+N15 -> 200 | Q15: 0 | R15: =IF(Q15="","",N(Q15)-P15) -> -200
A16: 10 | B16: 7243 TU 75 | C16: LASSAD AMRI | D16: PLATEAU | F16: 0 | H16: 0 | I16: =$F$3 -> 2 | J16: =IF(OR(H16="",I16=""),0,H16*I16) -> 0 | K16: 80 | L16: 20 | M16: 20 | N16: 0 | O16: 80 | P16: =J16+N(K16)+N(L16)+N(M16)+N(O16)+N16 -> 200 | Q16: 0 | R16: =IF(Q16="","",N(Q16)-P16) -> -200
A17: 11 | B17: 4188 TU 80 | C17: SAMI | D17: PLATEAU | E17: GAFSA/SKHIRA | F17: 280 | H17: 90 | I17: =$F$3 -> 2 | J17: =IF(OR(H17="",I17=""),0,H17*I17) -> 180 | K17: 80 | L17: 20 | M17: 20 | N17: 0 | O17: 80 | P17: =J17+N(K17)+N(L17)+N(M17)+N(O17)+N17 -> 380 | Q17: 560 | R17: =IF(Q17="","",N(Q17)-P17) -> 180
A18: 12 | B18: 2318 TU 155 | C18: KAMEL CH | D18: BENNE | E18: CHAGRA/ SB | F18: 220 | H18: 70 | I18: =$F$3 -> 2 | J18: =IF(OR(H18="",I18=""),0,H18*I18) -> 140 | K18: 80 | L18: 20 | M18: 20 | N18: 0 | O18: 80 | P18: =J18+N(K18)+N(L18)+N(M18)+N(O18)+N18 -> 340 | Q18: 820 | R18: =IF(Q18="","",N(Q18)-P18) -> 480
A19: 13 | B19: 788 TU 99 | C19: KAMEL ZAY | D19: BENNE | E19: CHAGRA | F19: 200 | H19: 68 | I19: =$F$3 -> 2 | J19: =IF(OR(H19="",I19=""),0,H19*I19) -> 136 | K19: 80 | L19: 20 | M19: 20 | N19: 0 | O19: 80 | P19: =J19+N(K19)+N(L19)+N(M19)+N(O19)+N19 -> 336 | Q19: 500 | R19: =IF(Q19="","",N(Q19)-P19) -> 164
A20: 14 | B20: 8564 TU 257 | C20: CHOKRI THAMER | D20: BENNE | E20: FAIEDH/SB/SP | F20: 320 | H20: 110 | I20: =$F$3 -> 2 | J20: =IF(OR(H20="",I20=""),0,H20*I20) -> 220 | K20: 400 | L20: 32 | M20: 20 | N20: 0 | O20: 80 | P20: =J20+N(K20)+N(L20)+N(M20)+N(O20)+N20 -> 752 | Q20: 978 | R20: =IF(Q20="","",N(Q20)-P20) -> 226
A21: 15 | B21: 8566 TU 257 | C21: HSAN REBII | D21: BENNE | E21: FAIEDH/SB/SP | F21: 320 | H21: 110 | I21: =$F$3 -> 2 | J21: =IF(OR(H21="",I21=""),0,H21*I21) -> 220 | K21: 400 | L21: 32 | M21: 20 | N21: 0 | O21: 80 | P21: =J21+N(K21)+N(L21)+N(M21)+N(O21)+N21 -> 752 | Q21: 978 | R21: =IF(Q21="","",N(Q21)-P21) -> 226
A22: 16 | I22: =$F$3 -> 2 | J22: =IF(OR(H22="",I22=""),0,H22*I22) -> 0 | L22: 0 | M22: 0 | N22: 0 | O22: 0 | P22: =J22+N(K22)+N(L22)+N(M22)+N(O22)+N22 -> 0 | Q22: 0 | R22: =IF(Q22="","",N(Q22)-P22) -> 0
A23: 17 | I23: =$F$3 -> 2 | J23: =IF(OR(H23="",I23=""),0,H23*I23) -> 0 | L23: 0 | M23: 0 | N23: 0 | O23: 0 | P23: =J23+N(K23)+N(L23)+N(M23)+N(O23)+N23 -> 0 | Q23: 0 | R23: =IF(Q23="","",N(Q23)-P23) -> 0
A24: 18 | I24: =$F$3 -> 2 | J24: =IF(OR(H24="",I24=""),0,H24*I24) -> 0 | L24: 0 | M24: 0 | O24: 0 | P24: =J24+N(K24)+N(L24)+N(M24)+N(O24)+N24 -> 0 | R24: =IF(Q24="","",N(Q24)-P24)
A26: TOTAL JOUR | F26: =SUM(F7:F24) -> 2870 | H26: =SUM(H7:H24) -> 1008 | J26: =SUM(J7:J24) -> 2016 | K26: =SUM(K7:K21) -> 3120 | L26: =SUM(L7:L21) -> 360 | M26: =SUM(M7:M21) -> 300 | N26: =SUM(N7:N23) -> 0 | O26: =SUM(O7:O21) -> 1200 | P26: =SUM(P7:P24) -> 6996 | Q26: =SUM(Q7:Q24) -> 7338 | R26: =SUM(R7:R24) -> 342
F27: Total km jour | H27: Total gasoil (L) | J27: Total montant gasoil | K27: totale charge | L27: totale assurance | M27: totale taxe | N27: totale maint | O27: totale charge pers | P27: Total coûts | Q27: Total prix livraison | R27: Résultat global

Sheet 10-02-26 
A1: TABLEAU DE SUIVI JOURNALIER — CAMIONS (PRODUIT FINI & MATIÈRE PREMIÈRE)
B2: *
A3: Date | C3: 46058 | D3: Prix gasoil / L (par défaut) | F3: 2 | G3: Devise | I3: TND
A4: Saisir les valeurs en bleu. Les colonnes Montant global gasoil, Coût total et Résultat se calculent automatiquement.
A6: N° | B6: Matricule camion | C6: Nom chauffeur | D6: Type transport | E6: Destination | F6: Kilométrage du jour (km) | G6: Kilométrage global (km) | H6: Quantité gasoil (L) | I6: Prix gasoil / L | J6: Montant global gasoil | K6: Charges fixes | L6: Montant assurance | M6: Montant taxe | N6: Maintenance | O6: Charge personnel | P6: Coût total | Q6: Prix livraison | R6: Résultat (livraison - coût) | S6: Remarques
A7: 1 | B7: 8565 TU 257 | C7: CHOKAIRI | D7: PLATEAU | E7: TUNIS | F7: 0 | H7: 0 | I7: =$F$3 -> 2 | J7: =IF(OR(H7="",I7=""),0,H7*I7) -> 0 | K7: 400 | L7: 32 | M7: 20 | N7: 0 | O7: 80 | P7: =J7+N(K7)+N(L7)+N(M7)+N(O7)+N7 -> 532 | Q7: 0 | R7: =IF(Q7="","",N(Q7)-P7) -> -532
A8: 2 | B8: 8563 TU 257 | C8: LASSAD CHATAOUI | D8: PLATEAU | E8: TUNIS | F8: 0 | H8: 0 | I8: =$F$3 -> 2 | J8: =IF(OR(H8="",I8=""),0,H8*I8) -> 0 | K8: 400 | L8: 32 | M8: 20 | N8: 0 | O8: 80 | P8: =J8+N(K8)+N(L8)+N(M8)+N(O8)+N8 -> 532 | Q8: 0 | R8: =IF(Q8="","",N(Q8)-P8) -> -532
A9: 3 | B9: 5305 TU 236 | C9: HAMZA | D9: PLATEAU | E9: SOUSSE | F9: 0 | H9: 0 | I9: =$F$3 -> 2 | J9: =IF(OR(H9="",I9=""),0,H9*I9) -> 0 | K9: 80 | L9: 20 | M9: 20 | N9: 0 | O9: 80 | P9: =J9+N(K9)+N(L9)+N(M9)+N(O9)+N9 -> 200 | Q9: 0 | R9: =IF(Q9="","",N(Q9)-P9) -> -200
A10: 4 | B10: 924 TU 98 | C10: IKRAMI | D10: PLATEAU | E10: DJERBA | F10: 0 | H10: 0 | I10: =$F$3 -> 2 | J10: =IF(OR(H10="",I10=""),0,H10*I10) -> 0 | K10: 80 | L10: 20 | M10: 20 | N10: 0 | O10: 80 | P10: =J10+N(K10)+N(L10)+N(M10)+N(O10)+N10 -> 200 | Q10: 0 | R10: =IF(Q10="","",N(Q10)-P10) -> -200
A11: 5 | B11: 6980 TU 101 | C11: ABDELBARI | D11: PLATEAU | E11: KEBILI/GABES | F11: 0 | H11: 0 | I11: =$F$3 -> 2 | J11: =IF(OR(H11="",I11=""),0,H11*I11) -> 0 | K11: 80 | L11: 20 | M11: 20 | N11: 0 | O11: 80 | P11: =J11+N(K11)+N(L11)+N(M11)+N(O11)+N11 -> 200 | Q11: 0 | R11: =IF(Q11="","",N(Q11)-P11) -> -200
A12: 6 | B12: 7775 TU 252 | C12: JAMIL | D12: PLATEAU | E12: MEHDIA/TUNIS | F12: 0 | H12: 0 | I12: =$F$3 -> 2 | J12: =IF(OR(H12="",I12=""),0,H12*I12) -> 0 | K12: 400 | L12: 20 | M12: 20 | N12: 0 | O12: 80 | P12: =J12+N(K12)+N(L12)+N(M12)+N(O12)+N12 -> 520 | Q12: 0 | R12: =IF(Q12="","",N(Q12)-P12) -> -520
A13: 7 | B13: 4176 TU 250 | C13: HEDI | D13: PLATEAU | E13: TUNIS | F13: 0 | H13: 0 | I13: =$F$3 -> 2 | J13: =IF(OR(H13="",I13=""),0,H13*I13) -> 0 | K13: 400 | L13: 32 | M13: 20 | N13: 0 | O13: 80 | P13: =J13+N(K13)+N(L13)+N(M13)+N(O13)+N13 -> 532 | Q13: 0 | R13: =IF(Q13="","",N(Q13)-P13) -> -532
A14: 8 | B14: 446 TU 228 | C14: MALEK | D14: PLATEAU | F14: 0 | H14: 0 | I14: =$F$3 -> 2 | J14: =IF(OR(H14="",I14=""),0,H14*I14) -> 0 | K14: 80 | L14: 20 | M14: 20 | N14: 0 | O14: 80 | P14: =J14+N(K14)+N(L14)+N(M14)+N(O14)+N14 -> 200 | Q14: 0 | R14: =IF(Q14="","",N(Q14)-P14) -> -200
A15: 9 | B15: 3380 TU 104 | D15: PLATEAU | F15: 0 | H15: 0 | I15: =$F$3 -> 2 | J15: =IF(OR(H15="",I15=""),0,H15*I15) -> 0 | K15: 80 | L15: 20 | M15: 20 | N15: 0 | O15: 80 | P15: =J15+N(K15)+N(L15)+N(M15)+N(O15)+N15 -> 200 | Q15: 0 | R15: =IF(Q15="","",N(Q15)-P15) -> -200
A16: 10 | B16: 7243 TU 75 | C16: LASSAD AMRI | D16: PLATEAU | E16: OUDHREF | F16: 0 | H16: 0 | I16: =$F$3 -> 2 | J16: =IF(OR(H16="",I16=""),0,H16*I16) -> 0 | K16: 80 | L16: 20 | M16: 20 | N16: 0 | O16: 80 | P16: =J16+N(K16)+N(L16)+N(M16)+N(O16)+N16 -> 200 | Q16: 0 | R16: =IF(Q16="","",N(Q16)-P16) -> -200
A17: 11 | B17: 4188 TU 80 | C17: SAMI | D17: PLATEAU | F17: 0 | H17: 0 | I17: =$F$3 -> 2 | J17: =IF(OR(H17="",I17=""),0,H17*I17) -> 0 | K17: 80 | L17: 20 | M17: 20 | N17: 0 | O17: 80 | P17: =J17+N(K17)+N(L17)+N(M17)+N(O17)+N17 -> 200 | Q17: 0 | R17: =IF(Q17="","",N(Q17)-P17) -> -200
A18: 12 | B18: 2318 TU 155 | C18: KAMEL CH | D18: BENNE | E18: CHAGRA/ CHAGRA | F18: 0 | H18: 0 | I18: =$F$3 -> 2 | J18: =IF(OR(H18="",I18=""),0,H18*I18) -> 0 | K18: 80 | L18: 20 | M18: 20 | N18: 0 | O18: 80 | P18: =J18+N(K18)+N(L18)+N(M18)+N(O18)+N18 -> 200 | Q18: 0 | R18: =IF(Q18="","",N(Q18)-P18) -> -200
A19: 13 | B19: 788 TU 99 | C19: KAMEL ZAY | D19: BENNE | F19: 0 | H19: 0 | I19: =$F$3 -> 2 | J19: =IF(OR(H19="",I19=""),0,H19*I19) -> 0 | K19: 80 | L19: 20 | M19: 20 | N19: 0 | O19: 80 | P19: =J19+N(K19)+N(L19)+N(M19)+N(O19)+N19 -> 200 | Q19: 0 | R19: =IF(Q19="","",N(Q19)-P19) -> -200
A20: 14 | B20: 8564 TU 257 | C20: CHOKRI THAMER | D20: BENNE | E20: FAIEDH/SP/2SB | F20: 0 | H20: 0 | I20: =$F$3 -> 2 | J20: =IF(OR(H20="",I20=""),0,H20*I20) -> 0 | K20: 400 | L20: 32 | M20: 20 | N20: 0 | O20: 80 | P20: =J20+N(K20)+N(L20)+N(M20)+N(O20)+N20 -> 532 | Q20: 0 | R20: =IF(Q20="","",N(Q20)-P20) -> -532
A21: 15 | B21: 8566 TU 257 | C21: HSAN REBII | D21: BENNE | E21: FAIEDH/SP/2SB | F21: 0 | H21: 0 | I21: =$F$3 -> 2 | J21: =IF(OR(H21="",I21=""),0,H21*I21) -> 0 | K21: 400 | L21: 32 | M21: 20 | N21: 0 | O21: 80 | P21: =J21+N(K21)+N(L21)+N(M21)+N(O21)+N21 -> 532 | Q21: 0 | R21: =IF(Q21="","",N(Q21)-P21) -> -532
A22: 16 | I22: =$F$3 -> 2 | J22: =IF(OR(H22="",I22=""),0,H22*I22) -> 0 | L22: 0 | M22: 0 | N22: 0 | O22: 0 | P22: =J22+N(K22)+N(L22)+N(M22)+N(O22)+N22 -> 0 | Q22: 0 | R22: =IF(Q22="","",N(Q22)-P22) -> 0
A23: 17 | I23: =$F$3 -> 2 | J23: =IF(OR(H23="",I23=""),0,H23*I23) -> 0 | L23: 0 | M23: 0 | N23: 0 | O23: 0 | P23: =J23+N(K23)+N(L23)+N(M23)+N(O23)+N23 -> 0 | Q23: 0 | R23: =IF(Q23="","",N(Q23)-P23) -> 0
A24: 18 | I24: =$F$3 -> 2 | J24: =IF(OR(H24="",I24=""),0,H24*I24) -> 0 | L24: 0 | M24: 0 | O24: 0 | P24: =J24+N(K24)+N(L24)+N(M24)+N(O24)+N24 -> 0 | R24: =IF(Q24="","",N(Q24)-P24)
A26: TOTAL JOUR | F26: =SUM(F7:F24) -> 0 | H26: =SUM(H7:H24) -> 0 | J26: =SUM(J7:J24) -> 0 | K26: =SUM(K7:K21) -> 3120 | L26: =SUM(L7:L21) -> 360 | M26: =SUM(M7:M21) -> 300 | N26: =SUM(N7:N23) -> 0 | O26: =SUM(O7:O21) -> 1200 | P26: =SUM(P7:P24) -> 4980 | Q26: =SUM(Q7:Q24) -> 0 | R26: =SUM(R7:R24) -> -4980
F27: Total km jour | H27: Total gasoil (L) | J27: Total montant gasoil | K27: totale charge | L27: totale assurance | M27: totale taxe | N27: totale maint | O27: totale charge pers | P27: Total coûts | Q27: Total prix livraison | R27: Résultat global

Sheet RECAP 02-26
A1: TABLEAU DE SUIVI JOURNALIER — CAMIONS (PRODUIT FINI & MATIÈRE PREMIÈRE)
B2: *
A3: Date | C3: 46054 | D3: Prix gasoil / L (par défaut) | F3: 2 | G3: Devise | I3: TND
A4: Saisir les valeurs en bleu. Les colonnes Montant global gasoil, Coût total et Résultat se calculent automatiquement.
A6: N° | B6: Matricule camion | C6: Nom chauffeur | D6: Type transport | E6: Destination | F6: Kilométrage du jour (km) | G6: Kilométrage global (km) | H6: Quantité gasoil (L) | I6: Prix gasoil / L | J6: Montant global gasoil | K6: Charges fixes | L6: Montant assurance | M6: Montant taxe | N6: Maintenance | O6: Charge personnel | P6: Coût total | Q6: Prix livraison | R6: Résultat (livraison - coût) | S6: Remarques
A7: 1 | B7: 8565 TU 257 | C7: CHOKAIRI | D7: PLATEAU | E7: TUNIS | F7: ='02-02-26'!F7+'03-02-26'!F7+'04-02-26'!F7+'05-02-26'!F7+'06-02-26'!F7 -> 1344 | H7: ='02-02-26'!H7+'03-02-26'!H7+'04-02-26'!H7+'05-02-26'!H7+'06-02-26'!H7 -> 405 | I7: =$F$3 -> 2 | J7: =IF(OR(H7="",I7=""),0,H7*I7) -> 810 | K7: ='02-02-26'!K7+'03-02-26'!K7+'04-02-26'!K7+'05-02-26'!K7+'06-02-26'!K7 -> 2000 | L7: ='02-02-26'!L7+'03-02-26'!L7+'04-02-26'!L7+'05-02-26'!L7+'06-02-26'!L7 -> 160 | M7: ='02-02-26'!M7+'03-02-26'!M7+'04-02-26'!L7+'05-02-26'!M7+'06-02-26'!M7 -> 112 | N7: ='02-02-26'!N7+'03-02-26'!N7+'04-02-26'!N7+'05-02-26'!N7+'06-02-26'!N7 -> 0 | O7: ='02-02-26'!O7+'03-02-26'!O7+'04-02-26'!O7+'05-02-26'!O7+'06-02-26'!O7 -> 400 | P7: =J7+N(K7)+N(L7)+N(M7)+N(O7)+N7 -> 3482 | Q7: ='02-02-26'!Q7+'03-02-26'!Q7+'04-02-26'!Q7+'05-02-26'!Q7+'06-02-26'!Q7 -> 1258 | R7: =IF(Q7="","",N(Q7)-P7) -> -2224
A8: 2 | B8: 8563 TU 257 | C8: LASSAD CHATAOUI | D8: PLATEAU | E8: TUNIS | F8: ='02-02-26'!F8+'03-02-26'!F8+'04-02-26'!F8+'05-02-26'!F8+'06-02-26'!F8 -> 2354 | H8: ='02-02-26'!H8+'03-02-26'!H8+'04-02-26'!H8+'05-02-26'!H8+'06-02-26'!H8 -> 700 | I8: =$F$3 -> 2 | J8: =IF(OR(H8="",I8=""),0,H8*I8) -> 1400 | K8: ='02-02-26'!K8+'03-02-26'!K8+'04-02-26'!K8+'05-02-26'!K8+'06-02-26'!K8 -> 2000 | L8: ='02-02-26'!L8+'03-02-26'!L8+'04-02-26'!L8+'05-02-26'!L8+'06-02-26'!L8 -> 160 | M8: ='02-02-26'!M8+'03-02-26'!M8+'04-02-26'!L8+'05-02-26'!M8+'06-02-26'!M8 -> 112 | N8: ='02-02-26'!N8+'03-02-26'!N8+'04-02-26'!N8+'05-02-26'!N8+'06-02-26'!N8 -> 2136 | O8: ='02-02-26'!O8+'03-02-26'!O8+'04-02-26'!O8+'05-02-26'!O8+'06-02-26'!O8 -> 400 | P8: =J8+N(K8)+N(L8)+N(M8)+N(O8)+N8 -> 6208 | Q8: ='02-02-26'!Q8+'03-02-26'!Q8+'04-02-26'!Q8+'05-02-26'!Q8+'06-02-26'!Q8 -> 3015 | R8: =IF(Q8="","",N(Q8)-P8) -> -3193
A9: 3 | B9: 5305 TU 236 | C9: HAMZA | D9: PLATEAU | E9: SOUSSE | F9: ='02-02-26'!F9+'03-02-26'!F9+'04-02-26'!F9+'05-02-26'!F9+'06-02-26'!F9 -> 794 | H9: ='02-02-26'!H9+'03-02-26'!H9+'04-02-26'!H9+'05-02-26'!H9+'06-02-26'!H9 -> 295 | I9: =$F$3 -> 2 | J9: =IF(OR(H9="",I9=""),0,H9*I9) -> 590 | K9: ='02-02-26'!K9+'03-02-26'!K9+'04-02-26'!K9+'05-02-26'!K9+'06-02-26'!K9 -> 400 | L9: ='02-02-26'!L9+'03-02-26'!L9+'04-02-26'!L9+'05-02-26'!L9+'06-02-26'!L9 -> 100 | M9: ='02-02-26'!M9+'03-02-26'!M9+'04-02-26'!L9+'05-02-26'!M9+'06-02-26'!M9 -> 100 | N9: ='02-02-26'!N9+'03-02-26'!N9+'04-02-26'!N9+'05-02-26'!N9+'06-02-26'!N9 -> 0 | O9: ='02-02-26'!O9+'03-02-26'!O9+'04-02-26'!O9+'05-02-26'!O9+'06-02-26'!O9 -> 400 | P9: =J9+N(K9)+N(L9)+N(M9)+N(O9)+N9 -> 1590 | Q9: ='02-02-26'!Q9+'03-02-26'!Q9+'04-02-26'!Q9+'05-02-26'!Q9+'06-02-26'!Q9 -> 1301 | R9: =IF(Q9="","",N(Q9)-P9) -> -289
A10: 4 | B10: 924 TU 98 | C10: IKRAMI | D10: PLATEAU | E10: DJERBA | F10: ='02-02-26'!F10+'03-02-26'!F10+'04-02-26'!F10+'05-02-26'!F10+'06-02-26'!F10 -> 1480 | H10: ='02-02-26'!H10+'03-02-26'!H10+'04-02-26'!H10+'05-02-26'!H10+'06-02-26'!H10 -> 480 | I10: =$F$3 -> 2 | J10: =IF(OR(H10="",I10=""),0,H10*I10) -> 960 | K10: ='02-02-26'!K10+'03-02-26'!K10+'04-02-26'!K10+'05-02-26'!K10+'06-02-26'!K10 -> 400 | L10: ='02-02-26'!L10+'03-02-26'!L10+'04-02-26'!L10+'05-02-26'!L10+'06-02-26'!L10 -> 100 | M10: ='02-02-26'!M10+'03-02-26'!M10+'04-02-26'!L10+'05-02-26'!M10+'06-02-26'!M10 -> 100 | N10: ='02-02-26'!N10+'03-02-26'!N10+'04-02-26'!N10+'05-02-26'!N10+'06-02-26'!N10 -> 1225.224 | O10: ='02-02-26'!O10+'03-02-26'!O10+'04-02-26'!O10+'05-02-26'!O10+'06-02-26'!O10 -> 400 | P10: =J10+N(K10)+N(L10)+N(M10)+N(O10)+N10 -> 3185.224 | Q10: ='02-02-26'!Q10+'03-02-26'!Q10+'04-02-26'!Q10+'05-02-26'!Q10+'06-02-26'!Q10 -> 2287 | R10: =IF(Q10="","",N(Q10)-P10) -> -898.224
A11: 5 | B11: 6980 TU 101 | C11: ABDELBARI | D11: PLATEAU | E11: KEBILI/GABES | F11: ='02-02-26'!F11+'03-02-26'!F11+'04-02-26'!F11+'05-02-26'!F11+'06-02-26'!F11 -> 1144 | H11: ='02-02-26'!H11+'03-02-26'!H11+'04-02-26'!H11+'05-02-26'!H11+'06-02-26'!H11 -> 355 | I11: =$F$3 -> 2 | J11: =IF(OR(H11="",I11=""),0,H11*I11) -> 710 | K11: ='02-02-26'!K11+'03-02-26'!K11+'04-02-26'!K11+'05-02-26'!K11+'06-02-26'!K11 -> 400 | L11: ='02-02-26'!L11+'03-02-26'!L11+'04-02-26'!L11+'05-02-26'!L11+'06-02-26'!L11 -> 100 | M11: ='02-02-26'!M11+'03-02-26'!M11+'04-02-26'!L11+'05-02-26'!M11+'06-02-26'!M11 -> 100 | N11: ='02-02-26'!N11+'03-02-26'!N11+'04-02-26'!N11+'05-02-26'!N11+'06-02-26'!N11 -> 420.957 | O11: ='02-02-26'!O11+'03-02-26'!O11+'04-02-26'!O11+'05-02-26'!O11+'06-02-26'!O11 -> 400 | P11: =J11+N(K11)+N(L11)+N(M11)+N(O11)+N11 -> 2130.957 | Q11: ='02-02-26'!Q11+'03-02-26'!Q11+'04-02-26'!Q11+'05-02-26'!Q11+'06-02-26'!Q11 -> 1768 | R11: =IF(Q11="","",N(Q11)-P11) -> -362.957
A12: 6 | B12: 7775 TU 252 | C12: JAMIL | D12: PLATEAU | E12: MEHDIA/TUNIS | F12: ='02-02-26'!F12+'03-02-26'!F12+'04-02-26'!F12+'05-02-26'!F12+'06-02-26'!F12 -> 2180 | H12: ='02-02-26'!H12+'03-02-26'!H12+'04-02-26'!H12+'05-02-26'!H12+'06-02-26'!H12 -> 650 | I12: =$F$3 -> 2 | J12: =IF(OR(H12="",I12=""),0,H12*I12) -> 1300 | K12: ='02-02-26'!K12+'03-02-26'!K12+'04-02-26'!K12+'05-02-26'!K12+'06-02-26'!K12 -> 2000 | L12: ='02-02-26'!L12+'03-02-26'!L12+'04-02-26'!L12+'05-02-26'!L12+'06-02-26'!L12 -> 100 | M12: ='02-02-26'!M12+'03-02-26'!M12+'04-02-26'!L12+'05-02-26'!M12+'06-02-26'!M12 -> 100 | N12: ='02-02-26'!N12+'03-02-26'!N12+'04-02-26'!N12+'05-02-26'!N12+'06-02-26'!N12 -> 0 | O12: ='02-02-26'!O12+'03-02-26'!O12+'04-02-26'!O12+'05-02-26'!O12+'06-02-26'!O12 -> 400 | P12: =J12+N(K12)+N(L12)+N(M12)+N(O12)+N12 -> 3900 | Q12: ='02-02-26'!Q12+'03-02-26'!Q12+'04-02-26'!Q12+'05-02-26'!Q12+'06-02-26'!Q12 -> 3691 | R12: =IF(Q12="","",N(Q12)-P12) -> -209
A13: 7 | B13: 4176 TU 250 | C13: HEDI | D13: PLATEAU | E13: TUNIS | F13: ='02-02-26'!F13+'03-02-26'!F13+'04-02-26'!F13+'05-02-26'!F13+'06-02-26'!F13 -> 2090 | H13: ='02-02-26'!H13+'03-02-26'!H13+'04-02-26'!H13+'05-02-26'!H13+'06-02-26'!H13 -> 645 | I13: =$F$3 -> 2 | J13: =IF(OR(H13="",I13=""),0,H13*I13) -> 1290 | K13: ='02-02-26'!K13+'03-02-26'!K13+'04-02-26'!K13+'05-02-26'!K13+'06-02-26'!K13 -> 2000 | L13: ='02-02-26'!L13+'03-02-26'!L13+'04-02-26'!L13+'05-02-26'!L13+'06-02-26'!L13 -> 160 | M13: ='02-02-26'!M13+'03-02-26'!M13+'04-02-26'!L13+'05-02-26'!M13+'06-02-26'!M13 -> 112 | N13: ='02-02-26'!N13+'03-02-26'!N13+'04-02-26'!N13+'05-02-26'!N13+'06-02-26'!N13 -> 0 | O13: ='02-02-26'!O13+'03-02-26'!O13+'04-02-26'!O13+'05-02-26'!O13+'06-02-26'!O13 -> 400 | P13: =J13+N(K13)+N(L13)+N(M13)+N(O13)+N13 -> 3962 | Q13: ='02-02-26'!Q13+'03-02-26'!Q13+'04-02-26'!Q13+'05-02-26'!Q13+'06-02-26'!Q13 -> 2620 | R13: =IF(Q13="","",N(Q13)-P13) -> -1342
A14: 8 | B14: 3380 TU 104 | C14: MALEK | D14: PLATEAU | F14: ='02-02-26'!F14+'03-02-26'!F14+'04-02-26'!F14+'05-02-26'!F14+'06-02-26'!F14 -> 0 | H14: ='02-02-26'!H14+'03-02-26'!H14+'04-02-26'!H14+'05-02-26'!H14+'06-02-26'!H14 -> 0 | I14: =$F$3 -> 2 | J14: =IF(OR(H14="",I14=""),0,H14*I14) -> 0 | K14: ='02-02-26'!K14+'03-02-26'!K14+'04-02-26'!K14+'05-02-26'!K14+'06-02-26'!K14 -> 400 | L14: ='02-02-26'!L14+'03-02-26'!L14+'04-02-26'!L14+'05-02-26'!L14+'06-02-26'!L14 -> 100 | M14: ='02-02-26'!M14+'03-02-26'!M14+'04-02-26'!L14+'05-02-26'!M14+'06-02-26'!M14 -> 100 | N14: ='02-02-26'!N14+'03-02-26'!N14+'04-02-26'!N14+'05-02-26'!N14+'06-02-26'!N14 -> 620 | O14: ='02-02-26'!O14+'03-02-26'!O14+'04-02-26'!O14+'05-02-26'!O14+'06-02-26'!O14 -> 400 | P14: =J14+N(K14)+N(L14)+N(M14)+N(O14)+N14 -> 1620 | Q14: ='02-02-26'!Q14+'03-02-26'!Q14+'04-02-26'!Q14+'05-02-26'!Q14+'06-02-26'!Q14 -> 0 | R14: =IF(Q14="","",N(Q14)-P14) -> -1620
A15: 9 | B15: 446 TU 228 | D15: PLATEAU | F15: ='02-02-26'!F15+'03-02-26'!F15+'04-02-26'!F15+'05-02-26'!F15+'06-02-26'!F15 -> 260 | H15: ='02-02-26'!H15+'03-02-26'!H15+'04-02-26'!H15+'05-02-26'!H15+'06-02-26'!H15 -> 80 | I15: =$F$3 -> 2 | J15: =IF(OR(H15="",I15=""),0,H15*I15) -> 160 | K15: ='02-02-26'!K15+'03-02-26'!K15+'04-02-26'!K15+'05-02-26'!K15+'06-02-26'!K15 -> 400 | L15: ='02-02-26'!L15+'03-02-26'!L15+'04-02-26'!L15+'05-02-26'!L15+'06-02-26'!L15 -> 100 | M15: ='02-02-26'!M15+'03-02-26'!M15+'04-02-26'!L15+'05-02-26'!M15+'06-02-26'!M15 -> 100 | N15: ='02-02-26'!N15+'03-02-26'!N15+'04-02-26'!N15+'05-02-26'!N15+'06-02-26'!N15 -> 446.25 | O15: ='02-02-26'!O15+'03-02-26'!O15+'04-02-26'!O15+'05-02-26'!O15+'06-02-26'!O15 -> 400 | P15: =J15+N(K15)+N(L15)+N(M15)+N(O15)+N15 -> 1606.25 | Q15: ='02-02-26'!Q15+'03-02-26'!Q15+'04-02-26'!Q15+'05-02-26'!Q15+'06-02-26'!Q15 -> 544 | R15: =IF(Q15="","",N(Q15)-P15) -> -1062.25
